<?xml version="1.0"?>
<robot name="myrobot">
  <!-- world joint -->
  <link name="world"/>

  <!-- relation between simulation world and our model -->
  <joint name="world_joint" type="fixed">
      <parent link="world"/>
      <child link="base_link"/> 
  </joint>

  <!-- base link -->
  <link name="base_link">
    <inertial>
      <mass value="1.0"/>
      <origin xyz="0 0 0.5" rpy="0 0 0"/>
      <inertia ixx="1.0" ixy="0.0" ixz="0.0"
                         iyy="1.0" iyz="0.0"
                                   izz="1.0"/>
    </inertial>
    <visual>
      <origin xyz="0 0 0.5" rpy="0 0 0"/>
      <geometry>
        <box size="0.1 0.1 1.0"/>
      </geometry>
    </visual>
    <collision>
      <origin xyz="0 0 0.5" rpy="0 0 0"/>
      <geometry>
        <box size="0.1 0.1 1.0"/>
      </geometry>
    </collision>
  </link>
  <gazebo reference="base_link">
    <material>Gazebo/Red</material>
  </gazebo>

  <!-- joint which connects base and tip -->
  <joint name="tip_joint" type="continuous">
    <parent link="base_link"/>
    <child link="tip_link"/>	
    <axis xyz="0 1 0"/>
    <origin xyz="0 0.1 1.0" rpy="0 0 0"/>
    <dynamics damping="0.7"/>
  </joint>
  <!-- transmission -->
  <transmission name="tip_trans">
    <type>transmission_interface/SimpleTransmission</type>
    <joint name="tip_joint"/> 
    <actuator name="tip_motor">
       <hardwareInterface>EffortJointInterface</hardwareInterface>
       <mechanismReduction>1</mechanismReduction>
    </actuator>
  </transmission>

  <!-- arm tip link -->
  <link name="tip_link">
    <inertial>
      <mass value="1.0"/>
      <origin xyz="0 0 0.25" rpy="0 0 0"/>
      <inertia ixx="1.0" ixy="0.0" ixz="0.0"
                         iyy="1.0" iyz="0.0"
                                   izz="1.0"/>
    </inertial>
    <visual>
      <origin xyz="0 0 0.25" rpy="0 0 0"/>
      <geometry>
        <box size="0.1 0.1 0.5"/>
      </geometry>
    </visual>
    <collision>
      <origin xyz="0 0 0.25" rpy="0 0 0"/>
      <geometry>
        <box size="0.1 0.1 0.5"/>
      </geometry>
    </collision>
  </link>
  <gazebo reference="tip_link">
    <material>Gazebo/Orange</material>
  </gazebo>

  <joint name="camera_joint" type="fixed">
    <parent link="tip_link"/>
    <child link="camera_link"/>
    <origin xyz="0 0 0.5" rpy="0 -1.57 0"/>
  </joint>

  <link name="camera_link">
    <inertial>
      <mass value="1e-6"/>
      <origin xyz="0.05 0 0" rpy="0 0 0"/>
      <inertia ixx="1e-6" ixy="0.0" ixz="0.0"
                         iyy="1.0" iyz="0.0"
                                   izz="1.0"/>
    </inertial>
    <visual>
      <origin xyz="0.05 0 0" rpy="0 1.57 0"/>
      <geometry>
        <cylinder radius="0.05" length="0.1"/>
      </geometry>
    </visual>
    <collision>
      <origin xyz="0.05 0 0" rpy="0 1.57 0"/>
      <geometry>
        <cylinder radius="0.05" length="0.1"/>
      </geometry>
    </collision>
  </link>
  <gazebo reference="camera_link">
    <material>Gazebo/FlatBlack</material>
  </gazebo>

  <!-- ros control plugin -->
  <gazebo>
    <plugin name="gazebo_ros_control" filename="libgazebo_ros_control.so">
      <robotNamespace>/myrobot</robotNamespace>
    </plugin>
  </gazebo>

  <!-- camera plugin -->
  <gazebo reference="camera_link">
    <sensor type="camera" name="tip_camera">
      <update_rate>30.0</update_rate>
      <camera name="tip_camera">
        <horizontal_fov>1.3962634</horizontal_fov>
        <image>
          <width>800</width>
          <height>600</height>
          <format>R8G8B8</format>
        </image>
        <clip>
          <near>0.05</near>
          <far>500</far>
        </clip>
        <noise>
          <type>gaussian</type>
          <mean>0.0</mean>
          <stddev>0.005</stddev>
        </noise>
      </camera>
      <plugin name="camera_controller" filename="libgazebo_ros_camera.so">
        <alwaysOn>true</alwaysOn>
        <updateRate>0.0</updateRate>
        <cameraName>myrobot/tip_camera</cameraName>
        <imageTopicName>image_raw</imageTopicName>
        <cameraInfoTopicName>camera_info</cameraInfoTopicName>
        <frameName>camera_link</frameName>
        <hackBaseline>0.07</hackBaseline>
        <distortionK1>0.0</distortionK1>
        <distortionK2>0.0</distortionK2>
        <distortionK3>0.0</distortionK3>
        <distortionT1>0.0</distortionT1>
        <distortionT2>0.0</distortionT2>
      </plugin>
    </sensor>
  </gazebo>
</robot>
